<mujoco model="urdf">
  <option gravity="0 0 0" />
  <default>
    <default class="robot">
      <default class="motor">
        <joint />
        <motor />
      </default>
      <default class="visual">
        <geom material="visualgeom" contype="0" conaffinity="0" group="2" />
      </default>
      <default class="collision">
        <geom material="collision_material" condim="3" contype="0" conaffinity="1" priority="1" group="1" solref="0.005 1" solimp="0.99 0.999 1e-05" friction="1 0.01 0.01" />
      </default>
    </default>
  </default>

  <compiler angle="radian" />

  <visual>
    <global azimuth="140" elevation="-30"/>
    <headlight ambient="0.3 0.3 0.3" diffuse="0.6 0.6 0.6" specular="0 0 0"/>
    <rgba haze="0.15 0.25 0.35 1"/>
  </visual>

  <statistic extent="0.4" center="0 -0.2 0.1"/>

  <asset>
    <texture type="skybox" colorspace="auto" builtin="gradient" rgb1="0.3 0.5 0.7" rgb2="0 0 0" width="512" height="3072"/>
    <texture type="2d" colorspace="auto" name="groundplane" builtin="checker" mark="edge" rgb1="0.2 0.3 0.4" rgb2="0.1 0.2 0.3" markrgb="0.8 0.8 0.8" width="300" height="300"/>
    <!-- <texture type="2d" colorspace="linear" name="small_meta_table_diffuse" file="assets/table/small_meta_table_diffuse.png"/> -->
    <material name="groundplane" texture="groundplane" texuniform="true" texrepeat="5 5" reflectance="0.2"/>
    <material name="black" rgba="0.55 0.55 0.55 1" />
    <material name="gray" rgba="0.9 0.9 0.9 1" />
    <material name="white" rgba="1.0 1.0 1.0 1" />
    <material name="red" rgba="1.0 0.0 0.0 1" />
    <material name="green" rgba="0.0 1.0 0.0 1" />
    <material name="blue" rgba="0.0 0.0 1.0 1" />
    <material name="yellow" rgba="1.0 1.0 0.0 1" />
    <material name="cyan" rgba="0.0 1.0 1.0 1" />
    <material name="magenta" rgba="1.0 0.0 1.0 1" />
    <material name="orange" rgba="1.0 0.65 0.0 1" />
    <material name="pink" rgba="1.0 0.75 0.8 1" />
    <material name="brown" rgba="0.6 0.3 0.1 1" />
    <material name="purple" rgba="0.5 0.0 0.5 1" />
    <material name="lightblue" rgba="0.5 0.7 1.0 1" />
    <material name="lightgreen" rgba="0.6 1.0 0.6 1" />
    <material name="collision_material" rgba="1 1 1 0" />
    <mesh name="base_link.STL" file="../meshes/base_link.STL" />
    <mesh name="Link1.STL" file="../meshes/Link1.STL" />
    <mesh name="Link2.STL" file="../meshes/Link2.STL" />
    <mesh name="Link3.STL" file="../meshes/Link3.STL" />
    <mesh name="Link4.STL" file="../meshes/Link4.STL" />
    <mesh name="Link5.STL" file="../meshes/Link5.STL" />
    <mesh name="Link6.STL" file="../meshes/Link6.STL" />
    <mesh name="paw_L.STL" file="../meshes/paw_L.STL" />
    <mesh name="paw_R.STL" file="../meshes/paw_R.STL" />
  </asset>

  <worldbody>
    <geom name="floor" size="0 0 0.05" type="plane" material="groundplane"/>
    <body name="base_link" pos="0.00000000 0.00000000 0.00000000" quat="1 0 0 0" childclass="robot">
      <freejoint name="floating_base" />
      <geom name="base_link_collision" pos="0 0 0" quat="1.0 0.0 0.0 0.0" type="mesh" mesh="base_link.STL" class="collision" />
      <geom name="base_link_visual" pos="0 0 0" quat="1.0 0.0 0.0 0.0" material="lightblue" type="mesh" mesh="base_link.STL" class="visual" />
      <body name="Link1" pos="0 0 0.0583" quat="1.0 0.0 0.0 0.0">
        <joint name="joint1" type="hinge" ref="0.0" class="motor" range="-3.1416 3.1416" axis="0 0 1" />
        <inertial pos="-0.000774616089845266 -0.00172866489028181 0.03205840924185" quat="1.0 0.0 0.0 0.0" mass="0.232358620887441" diaginertia="0.000129804094078772 0.000207295908232797 0.000113499232502988" />
        <geom name="Link1_collision" pos="0 0 0" quat="1.0 0.0 0.0 0.0" type="mesh" mesh="Link1.STL" class="collision" />
        <geom name="Link1_visual" pos="0 0 0" quat="1.0 0.0 0.0 0.0" material="lightblue" type="mesh" mesh="Link1.STL" class="visual" />
        <body name="Link2" pos="0 0.00016275 0.053" quat="0.7071054825112363 -0.7071080798594735 0.0 0.0">
          <joint name="joint2" type="hinge" ref="0.0" class="motor" range="-3.1416 0" axis="0 0 -1" />
          <inertial pos="-0.195396941315485 -0.000731552234369756 -0.000432156329869182" quat="1.0 0.0 0.0 0.0" mass="0.899590919391631" diaginertia="0.000590629609535892 0.00787865404980512 0.00760820979443672" />
          <geom name="Link2_collision" pos="0 0 0" quat="1.0 0.0 0.0 0.0" type="mesh" mesh="Link2.STL" class="collision" />
          <geom name="Link2_visual" pos="0 0 0" quat="1.0 0.0 0.0 0.0" material="lightblue" type="mesh" mesh="Link2.STL" class="visual" />
          <body name="Link3" pos="-0.37469 0 0" quat="1.0 0.0 0.0 0.0">
            <joint name="joint3" type="hinge" ref="0.0" class="motor" range="0 3.1416" axis="0 0 -1" />
            <inertial pos="0.127757735465632 -0.0562689140753057 -0.0022062815259123" quat="1.0 0.0 0.0 0.0" mass="0.631326195259651" diaginertia="0.000706012982096896 0.00331598725903545 0.00339502390868796" />
            <geom name="Link3_collision" pos="0 0 0" quat="1.0 0.0 0.0 0.0" type="mesh" mesh="Link3.STL" class="collision" />
            <geom name="Link3_visual" pos="0 0 0" quat="1.0 0.0 0.0 0.0" material="cyan" type="mesh" mesh="Link3.STL" class="visual" />
            <body name="Link4" pos="0.27731 -0.065116 0" quat="1.0 0.0 0.0 0.0">
              <joint name="joint4" type="hinge" ref="0.0" class="motor" range="-1.57 1.7" axis="0 0 -1" />
              <inertial pos="0.0560720069442845 -0.0496923140736883 -0.000758186015161692" quat="1.0 0.0 0.0 0.0" mass="0.229139782654743" diaginertia="6.88400924999392e-05 0.000105740501519538 8.47394013343152e-05" />
              <geom name="Link4_collision" pos="0 0 0" quat="1.0 0.0 0.0 0.0" type="mesh" mesh="Link4.STL" class="collision" />
              <geom name="Link4_visual" pos="0 0 0" quat="1.0 0.0 0.0 0.0" material="lightblue" type="mesh" mesh="Link4.STL" class="visual" />
              <body name="Link5" pos="0.078469 -0.039355 -0.0017" quat="0.7071054825112363 0.7071080798594735 0.0 0.0">
                <joint name="joint5" type="hinge" ref="0.0" class="motor" range="-2 2" axis="0 0 1" />
                <inertial pos="0.00748120796881852 8.41512901280446E-06 -0.0344661276886921" quat="1.0 0.0 0.0 0.0" mass="0.129464168351204" diaginertia="5.61207590453651e-05 3.95548125877818e-05 3.7353203534913e-05" />
                <geom name="Link5_collision" pos="0 0 0" quat="1.0 0.0 0.0 0.0" type="mesh" mesh="Link5.STL" class="collision" />
                <geom name="Link5_visual" pos="0 0 0" quat="1.0 0.0 0.0 0.0" material="lightblue" type="mesh" mesh="Link5.STL" class="visual" />
                <body name="Link6" pos="0.03 0 -0.03797" quat="0.7071054825112363 0.0 0.7071080798594735 0.0">
                  <joint name="joint6" type="hinge" ref="0.0" class="motor" range="-3.1416 3.1416" axis="0 0 1" />
                  <inertial pos="-0.00393023978152518 7.30355256789699E-07 0.0376749122877705" quat="1.0 0.0 0.0 0.0" mass="0.264350548769511" diaginertia="0.000188068034586868 6.4781512330863e-05 0.000230565452512835" />
                  <geom name="Link6_collision" pos="0 0 0" quat="1.0 0.0 0.0 0.0" type="mesh" mesh="Link6.STL" class="collision" />
                  <geom name="Link6_visual" pos="0 0 0" quat="1.0 0.0 0.0 0.0" material="lightblue" type="mesh" mesh="Link6.STL" class="visual" />
                  <body name="paw_L" pos="-0.00024999 0 0.178" quat="0.5015956006783602 0.49839744860659485 -0.5015974431452642 0.49839927932600886">
                    <joint name="joint_L" type="slide" ref="0.0" class="motor" range="0 0.05" axis="0 0 1" />
                    <inertial pos="-0.090895090478183 -6.00141875001237E-06 0.0136470306399902" quat="1.0 0.0 0.0 0.0" mass="0.0351838793613885" diaginertia="2.50379153020923e-06 6.43905505265882e-06 6.46624800580554e-06" />
                    <geom name="paw_L_collision" pos="0 0 0" quat="1.0 0.0 0.0 0.0" type="mesh" mesh="paw_L.STL" class="collision" />
                    <geom name="paw_L_visual" pos="0 0 0" quat="1.0 0.0 0.0 0.0" material="lightblue" type="mesh" mesh="paw_L.STL" class="visual" />
                  </body>
                  <body name="paw_R" pos="-0.00024999 0 0.178" quat="0.4983956061397123 -0.5015974313910281 -0.49839743685235854 -0.5015992738646567">
                    <joint name="joint_R" type="slide" ref="0.0" class="motor" range="0 0.05" axis="0 0 1" />
                    <inertial pos="-0.0908950905438273 0.000411120661349101 0.0136389885509623" quat="1.0 0.0 0.0 0.0" mass="0.0351838790769574" diaginertia="2.50379150698295e-06 6.43905501489629e-06 6.46624797873592e-06" />
                    <geom name="paw_R_collision" pos="0 0 0" quat="1.0 0.0 0.0 0.0" type="mesh" mesh="paw_R.STL" class="collision" />
                    <geom name="paw_R_visual" pos="0 0 0" quat="1.0 0.0 0.0 0.0" material="lightblue" type="mesh" mesh="paw_R.STL" class="visual" />
                  </body>
                </body>
              </body>
            </body>
          </body>
        </body>
      </body>
      <site name="base_link_site" pos="0 0 0" quat="1 0 0 0" />
      <camera name="front_camera" mode="track" fovy="90.0" quat="4.329780281177467e-17 4.329780281177466e-17 0.7071067811865475 0.7071067811865476" pos="0.0 2.0 0.5" />
      <camera name="side_camera" mode="track" fovy="90.0" quat="-0.5 -0.4999999999999999 0.5 0.5000000000000001" pos="-2.0 0.0 0.5" />
    </body>
  </worldbody>

  <actuator>
    <motor name="joint1_ctrl" joint="joint1" class="motor" />
    <motor name="joint2_ctrl" joint="joint2" class="motor" />
    <motor name="joint3_ctrl" joint="joint3" class="motor" />
    <motor name="joint4_ctrl" joint="joint4" class="motor" />
    <motor name="joint5_ctrl" joint="joint5" class="motor" />
    <motor name="joint6_ctrl" joint="joint6" class="motor" />
    <motor name="joint_L_ctrl" joint="joint_L" class="motor" />
    <motor name="joint_R_ctrl" joint="joint_R" class="motor" />
  </actuator>

  <contact>
    <exclude body1="base_link" body2="Link1" />
    <exclude body1="Link1" body2="Link2" />
    <exclude body1="Link2" body2="Link3" />
    <exclude body1="Link3" body2="Link4" />
    <exclude body1="Link4" body2="Link5" />
    <exclude body1="Link5" body2="Link6" />
    <exclude body1="Link6" body2="paw_L" />
    <exclude body1="Link6" body2="paw_R" />
  </contact>

  <sensor>
    <framepos name="base_link_site_pos" objtype="site" objname="base_link_site" />
    <framequat name="base_link_site_quat" objtype="site" objname="base_link_site" />
    <framelinvel name="base_link_site_linvel" objtype="site" objname="base_link_site" />
    <frameangvel name="base_link_site_angvel" objtype="site" objname="base_link_site" />
    <velocimeter name="base_link_site_vel" site="base_link_site" />
  </sensor>
</mujoco>