<?xml version="1.0" encoding="utf-8"?>
<!-- This URDF was automatically created by SolidWorks to URDF Exporter! Originally created by Stephen Brawner (brawner@gmail.com) 
     Commit Version: 1.6.0-4-g7f85cfe  Build Version: 1.6.7995.38578
     For more information, please see http://wiki.ros.org/sw_urdf_exporter -->
<robot
  name="arm_urdf">
  <link
    name="base_link">
    <inertial>
      <origin
        xyz="2.02358961017435E-17 -1.28021133048406E-17 0.00247211117961637"
        rpy="0 0 0" />
      <mass
        value="0.134082046127295" />
      <inertia
        ixx="0.000235431478598656"
        ixy="-3.10241995332291E-19"
        ixz="-5.90497799252091E-21"
        iyy="7.76678354570903E-05"
        iyz="1.61857434809876E-18"
        izz="0.00031253704348686" />
    </inertial>
    <visual>
      <origin
        xyz="0 0 0"
        rpy="0 0 0" />
      <geometry>
        <mesh
          filename="package://arm_urdf/meshes/base_link.STL" />
      </geometry>
      <material
        name="">
        <color
          rgba="0.752941176470588 0.752941176470588 0.752941176470588 1" />
      </material>
    </visual>
    <collision>
      <origin
        xyz="0 0 0"
        rpy="0 0 0" />
      <geometry>
        <mesh
          filename="package://arm_urdf/meshes/base_link.STL" />
      </geometry>
    </collision>
  </link>
  <link
    name="Link1">
    <inertial>
      <origin
        xyz="-0.00103208444268989 -0.00194942220625668 0.0295370756961767"
        rpy="0 0 0" />
      <mass
        value="0.193702050380756" />
      <inertia
        ixx="0.000119342553291515"
        ixy="-2.96106158064204E-08"
        ixz="3.10792693053874E-07"
        iyy="0.00019349914824527"
        iyz="3.09191878489648E-06"
        izz="9.07708697191066E-05" />
    </inertial>
    <visual>
      <origin
        xyz="0 0 0"
        rpy="0 0 0" />
      <geometry>
        <mesh
          filename="package://arm_urdf/meshes/Link1.STL" />
      </geometry>
      <material
        name="">
        <color
          rgba="0.752941176470588 0.752941176470588 0.752941176470588 1" />
      </material>
    </visual>
    <collision>
      <origin
        xyz="0 0 0"
        rpy="0 0 0" />
      <geometry>
        <mesh
          filename="package://arm_urdf/meshes/Link1.STL" />
      </geometry>
    </collision>
  </link>
  <joint
    name="joint1"
    type="revolute">
    <origin
      xyz="0 0 0.0754999999999988"
      rpy="0 0 0" />
    <parent
      link="base_link" />
    <child
      link="Link1" />
    <axis
      xyz="0 0 1" />
    <limit
      lower="-3.1416"
      upper="3.1416"
      effort="0"
      velocity="0" />
  </joint>
  <link
    name="Link2">
    <inertial>
      <origin
        xyz="-0.205265919939079 -0.000665038801470563 0.000170929466844783"
        rpy="0 0 0" />
      <mass
        value="0.961257204112951" />
      <inertia
        ixx="0.0006040358111544"
        ixy="-0.000207288004998823"
        ixz="5.83830622500793E-09"
        iyy="0.00794246727593146"
        iyz="1.04442375246467E-10"
        izz="0.00768053439263201" />
    </inertial>
    <visual>
      <origin
        xyz="0 0 0"
        rpy="0 0 0" />
      <geometry>
        <mesh
          filename="package://arm_urdf/meshes/Link2.STL" />
      </geometry>
      <material
        name="">
        <color
          rgba="0.752941176470588 0.752941176470588 0.752941176470588 1" />
      </material>
    </visual>
    <collision>
      <origin
        xyz="0 0 0"
        rpy="0 0 0" />
      <geometry>
        <mesh
          filename="package://arm_urdf/meshes/Link2.STL" />
      </geometry>
    </collision>
  </link>
  <joint
    name="joint2"
    type="revolute">
    <origin
      xyz="0 0.000162754502863236 0.045"
      rpy="-1.5707963267949 0 0" />
    <parent
      link="Link1" />
    <child
      link="Link2" />
    <axis
      xyz="0 0 -1" />
    <limit
      lower="-3.1416"
      upper="0"
      effort="0"
      velocity="0" />
  </joint>
  <link
    name="Link3">
    <inertial>
      <origin
        xyz="0.129425387898488 -0.0535598680676597 0.000991973235645757"
        rpy="0 0 0" />
      <mass
        value="0.636499328321956" />
      <inertia
        ixx="0.000677557160439994"
        ixy="0.000656452467598906"
        ixz="-2.2228453265698E-09"
        iyy="0.00335905835678217"
        iyz="3.79358721527472E-10"
        izz="0.0034092136084591" />
    </inertial>
    <visual>
      <origin
        xyz="0 0 0"
        rpy="0 0 0" />
      <geometry>
        <mesh
          filename="package://arm_urdf/meshes/Link3.STL" />
      </geometry>
      <material
        name="">
        <color
          rgba="0.752941176470588 0.752941176470588 0.752941176470588 1" />
      </material>
    </visual>
    <collision>
      <origin
        xyz="0 0 0"
        rpy="0 0 0" />
      <geometry>
        <mesh
          filename="package://arm_urdf/meshes/Link3.STL" />
      </geometry>
    </collision>
  </link>
  <joint
    name="joint3"
    type="revolute">
    <origin
      xyz="-0.374682908117834 0 0"
      rpy="0 0 0" />
    <parent
      link="Link2" />
    <child
      link="Link3" />
    <axis
      xyz="0 0 -1" />
    <limit
      lower="0"
      upper="3.1416"
      effort="0"
      velocity="0" />
  </joint>
  <link
    name="Link4">
    <inertial>
      <origin
        xyz="0.0503608485381376 -0.0479897254446679 0.00251539617023503"
        rpy="0 0 0" />
      <mass
        value="0.203247894255973" />
      <inertia
        ixx="5.82389959380398E-05"
        ixy="1.13121591958774E-05"
        ixz="-3.78282232063766E-07"
        iyy="8.47242929447002E-05"
        iyz="3.69488542717129E-07"
        izz="7.5373102157647E-05" />
    </inertial>
    <visual>
      <origin
        xyz="0 0 0"
        rpy="0 0 0" />
      <geometry>
        <mesh
          filename="package://arm_urdf/meshes/Link4.STL" />
      </geometry>
      <material
        name="">
        <color
          rgba="0.752941176470588 0.752941176470588 0.752941176470588 1" />
      </material>
    </visual>
    <collision>
      <origin
        xyz="0 0 0"
        rpy="0 0 0" />
      <geometry>
        <mesh
          filename="package://arm_urdf/meshes/Link4.STL" />
      </geometry>
    </collision>
  </link>
  <joint
    name="joint4"
    type="revolute">
    <origin
      xyz="0.278628579385124 -0.0592382999999998 0"
      rpy="0 0 0" />
    <parent
      link="Link3" />
    <child
      link="Link4" />
    <axis
      xyz="0 0 -1" />
    <limit
      lower="-1.8"
      upper="1.4"
      effort="0"
      velocity="0" />
  </joint>
  <link
    name="Link5">
    <inertial>
      <origin
        xyz="0.00747823991092132 4.53753176555584E-06 -0.0354685769046937"
        rpy="0 0 0" />
      <mass
        value="0.129444975569405" />
      <inertia
        ixx="5.61105171724285E-05"
        ixy="1.65540880132635E-09"
        ixz="8.88312733793737E-08"
        iyy="3.95537258949049E-05"
        iyz="-2.59369859902226E-08"
        izz="3.73439689526255E-05" />
    </inertial>
    <visual>
      <origin
        xyz="0 0 0"
        rpy="0 0 0" />
      <geometry>
        <mesh
          filename="package://arm_urdf/meshes/Link5.STL" />
      </geometry>
      <material
        name="">
        <color
          rgba="0.752941176470588 0.752941176470588 0.752941176470588 1" />
      </material>
    </visual>
    <collision>
      <origin
        xyz="0 0 0"
        rpy="0 0 0" />
      <geometry>
        <mesh
          filename="package://arm_urdf/meshes/Link5.STL" />
      </geometry>
    </collision>
  </link>
  <joint
    name="joint5"
    type="revolute">
    <origin
      xyz="0.0757983251348466 -0.0451729469104281 0.00145360367269375"
      rpy="1.57079632679491 0 -0.0624375112509467" />
    <parent
      link="Link4" />
    <child
      link="Link5" />
    <axis
      xyz="0 0 1" />
    <limit
      lower="-2"
      upper="2"
      effort="0"
      velocity="0" />
  </joint>
  <link
    name="Link6">
    <inertial>
      <origin
        xyz="-0.00567807730938441 -1.21838465311675E-06 0.0362460602081103"
        rpy="0 0 0" />
      <mass
        value="0.280724147013864" />
      <inertia
        ixx="0.00019197353113977"
        ixy="2.85736273423944E-06"
        ixz="4.03683979392565E-06"
        iyy="6.99668147778418E-05"
        iyz="-1.42629873692871E-09"
        izz="0.000238260246809292" />
    </inertial>
    <visual>
      <origin
        xyz="0 0 0"
        rpy="0 0 0" />
      <geometry>
        <mesh
          filename="package://arm_urdf/meshes/Link6.STL" />
      </geometry>
      <material
        name="">
        <color
          rgba="0.752941176470588 0.752941176470588 0.752941176470588 1" />
      </material>
    </visual>
    <collision>
      <origin
        xyz="0 0 0"
        rpy="0 0 0" />
      <geometry>
        <mesh
          filename="package://arm_urdf/meshes/Link6.STL" />
      </geometry>
    </collision>
  </link>
  <joint
    name="joint6"
    type="revolute">
    <origin
      xyz="0.03 0 -0.03897"
      rpy="1.5548 1.5708 1.555" />
    <parent
      link="Link5" />
    <child
      link="Link6" />
    <axis
      xyz="0 0 1" />
    <limit
      lower="-3.1416"
      upper="3.1416"
      effort="0"
      velocity="0" />
  </joint>
  <link
    name="paw_L">
    <inertial>
      <origin
        xyz="9.35231439744555E-05 -0.0137500197972551 -0.0913767701447353"
        rpy="0 0 0" />
      <mass
        value="0.0349061573619814" />
      <inertia
        ixx="6.19680571350084E-06"
        ixy="1.36106704578976E-09"
        ixz="4.79293587653369E-09"
        iyy="6.24551608064922E-06"
        iyz="-7.68569913002348E-07"
        izz="2.47027112009208E-06" />
    </inertial>
    <visual>
      <origin
        xyz="0 0 0"
        rpy="0 0 0" />
      <geometry>
        <mesh
          filename="package://arm_urdf/meshes/paw_L.STL" />
      </geometry>
      <material
        name="">
        <color
          rgba="0.752941176470588 0.752941176470588 0.752941176470588 1" />
      </material>
    </visual>
    <collision>
      <origin
        xyz="0 0 0"
        rpy="0 0 0" />
      <geometry>
        <mesh
          filename="package://arm_urdf/meshes/paw_L.STL" />
      </geometry>
    </collision>
  </link>
  <joint
    name="joint_L"
    type="prismatic">
    <origin
      xyz="-0.00024999 0 0.178"
      rpy="0 0 0" />
    <parent
      link="Link6" />
    <child
      link="paw_L" />
    <axis
      xyz="-0.0063635 0.99998 0" />
    <limit
      lower="-0.05"
      upper="0"
      effort="0"
      velocity="0" />
  </joint>
  <link
    name="paw_R">
    <inertial>
      <origin
        xyz="0.00032695949914377 0.0137445912158596 -0.0913767921396004"
        rpy="0 0 0" />
      <mass
        value="0.0349061463686987" />
      <inertia
        ixx="6.19678970195764E-06"
        ixy="1.36125633932835E-09"
        ixz="-5.77995570762738E-09"
        iyy="6.24550024592171E-06"
        iyz="7.6875728037317E-07"
        izz="2.4702709784782E-06" />
    </inertial>
    <visual>
      <origin
        xyz="0 0 0"
        rpy="0 0 0" />
      <geometry>
        <mesh
          filename="package://arm_urdf/meshes/paw_R.STL" />
      </geometry>
      <material
        name="">
        <color
          rgba="0.752941176470588 0.752941176470588 0.752941176470588 1" />
      </material>
    </visual>
    <collision>
      <origin
        xyz="0 0 0"
        rpy="0 0 0" />
      <geometry>
        <mesh
          filename="package://arm_urdf/meshes/paw_R.STL" />
      </geometry>
    </collision>
  </link>
  <joint
    name="joint_R"
    type="prismatic">
    <origin
      xyz="-0.00024999 0 0.178"
      rpy="0 0 0" />
    <parent
      link="Link6" />
    <child
      link="paw_R" />
    <axis
      xyz="-0.0063635 0.99998 0" />
    <limit
      lower="0"
      upper="0.05"
      effort="0"
      velocity="0" />
  </joint>
</robot>